Workbook

Sheet Dashboard
A1: Law & Order Universe - Complete Chronological Viewing Guide
A2: Professional master guide built from your uploaded workbook. Use the Chronological Guide tab from top to bottom; update Status as you watch.
A4: Metric | B4: Value
A5: Total guide entries | B5: 1796
A6: Shows included | B6: 14
A7: Earliest air date | B7: 33129
A8: Latest air date | B8: 46156
A9: Rows with episode titles from source | B9: 395
A10: Crossover/guest reference rows | B10: 87
A12: Show | B12: Entries
A13: Conviction | B13: 13
A14: Criminal Intent | B14: 194
A15: Deadline | B15: 13
A16: Homicide: Life on the Street | B16: 99
A17: In Plain Sight | B17: 61
A18: Law & Order | B18: 544
A19: Law & Order Toronto: Criminal Intent | B19: 20
A20: Law & Order: LA | B20: 22
A21: Law & Order: Organized Crime | B21: 75
A22: Law & Order: SVU | B22: 594
A23: Law & Order: UK | B23: 53
A24: NY Undercover | B24: 88
... A26: True Crime | B26: 8

Sheet Chronological Guide
A1: # | B1: Status | C1: Air Date | D1: Show | E1: Season | F1: Episode | G1: Code | H1: Title | I1: Crossover / Viewing Notes | J1: Source Watch # | K1: Era | L1: Source Tab | M1: Show Theme Color
A2: 1 | B2: Not Started | C2: 33129 | D2: Law & Order | E2: 1 | F2: 1 | G2: 01.01 | H2: Prescription for Death | K2: 1990–2001 | L2: 1990-2001 (w epi names) | M2: #b91c1c
A3: 2 | B3: Not Started | C3: 33136 | D3: Law & Order | E3: 1 | F3: 2 | G3: 01.02 | H3: Subterranean Homeboy Blues | K3: 1990–2001 | L3: 1990-2001 (w epi names) | M3: #b91c1c
A4: 3 | B4: Not Started | C4: 33150 | D4: Law & Order | E4: 1 | F4: 9 | G4: 01.09 | H4: Indifference | K4: 1990–2001 | L4: 1990-2001 (w epi names) | M4: #b91c1c
A5: 4 | B5: Not Started | C5: 33157 | D5: Law & Order | E5: 1 | F5: 3 | G5: 01.03 | H5: The Reaper's Helper | K5: 1990–2001 | L5: 1990-2001 (w epi names) | M5: #b91c1c
A6: 5 | B6: Not Started | C6: 33169 | D6: Law & Order | E6: 1 | F6: 4 | G6: 01.04 | H6: Kiss the Girls and Make Them Die | K6: 1990–2001 | L6: 1990-2001 (w epi names) | M6: #b91c1c
A7: 6 | B7: Not Started | C7: 33176 | D7: Law & Order | E7: 1 | F7: 5 | G7: 01.05 | H7: Happily Ever After | K7: 1990–2001 | L7: 1990-2001 (w epi names) | M7: #b91c1c
A8: 7 | B8: Not Started | C8: 33190 | D8: Law & Order | E8: 1 | F8: 6 | G8: 01.06 | H8: Everybody's Favorite Bagman | K8: 1990–2001 | L8: 1990-2001 (w epi names) | M8: #b91c1c
A9: 8 | B9: Not Started | C9: 33197 | D9: Law & Order | E9: 1 | F9: 7 | G9: 01.07 | H9: By Hooker, By Crook | K9: 1990–2001 | L9: 1990-2001 (w epi names) | M9: #b91c1c
A10: 9 | B10: Not Started | C10: 33204 | D10: Law & Order | E10: 1 | F10: 8 | G10: 01.08 | H10: Poison Ivy | K10: 1990–2001 | L10: 1990-2001 (w epi names) | M10: #b91c1c
A11: 10 | B11: Not Started | C11: 33211 | D11: Law & Order | E11: 1 | F11: 10 | G11: 01.10 | H11: Prisoner of Love | K11: 1990–2001 | L11: 1990-2001 (w epi names) | M11: #b91c1c
A12: 11 | B12: Not Started | C12: 33218 | D12: Law & Order | E12: 1 | F12: 11 | G12: 01.11 | H12: Out of the Half-Light | K12: 1990–2001 | L12: 1990-2001 (w epi names) | M12: #b91c1c
A13: 12 | B13: Not Started | C13: 33246 | D13: Law & Order | E13: 1 | F13: 12 | G13: 01.12 | H13: Life Choice | K13: 1990–2001 | L13: 1990-2001 (w epi names) | M13: #b91c1c
... A45: 44 | B45: Not Started | C45: 33736 | D45: Law & Order | E45: 2 | F45: 22 | G45: 02.22 | H45: The Working Stiff | K45: 1990–2001 | L45: 1990-2001 (w epi names) | M45: #b91c1c
A46: 45 | B46: Not Started | C46: 33870 | D46: Law & Order | E46: 3 | F46: 1 | G46: 03.01 | H46: Skin Deep | I46: Homicide Season 1-7 & movie | J46: 1 | K46: 1990–2001 | L46: 1990-2001 (w epi names) | M46: #b91c1c
A47: 46 | B47: Not Started | C47: 33877 | D47: Law & Order | E47: 3 | F47: 2 | G47: 03.02 | H47: Conspiracy | I47: NY Undercover Season 1-4 | J47: 2 | K47: 1990–2001 | L47: 1990-2001 (w epi names) | M47: #b91c1c
A48: 47 | B48: Not Started | C48: 33884 | D48: Law & Order | E48: 3 | F48: 3 | G48: 03.03 | H48: Forgiveness | I48: SVU Season 1-2 | J48: 3 | K48: 1990–2001 | L48: 1990-2001 (w epi names) | M48: #b91c1c
A49: 48 | B49: Not Started | C49: 33891 | D49: Law & Order | E49: 3 | F49: 4 | G49: 03.04 | H49: The Corporate Veil | I49: Deadline Season 1 | J49: 4 | K49: 1990–2001 | L49: 1990-2001 (w epi names) | M49: #b91c1c
A50: 49 | B50: Not Started | C50: 33898 | D50: Law & Order | E50: 3 | F50: 5 | G50: 03.05 | H50: Wedded Bliss | I50: *= aired out of order | J50: 5 | K50: 1990–2001 | L50: 1990-2001 (w epi names) | M50: #b91c1c
A51: 50 | B51: Not Started | C51: 33912 | D51: Law & Order | E51: 3 | F51: 6 | G51: 03.06 | H51: Helpless | J51: 6 | K51: 1990–2001 | L51: 1990-2001 (w epi names) | M51: #b91c1c
A52: 51 | B52: Not Started | C52: 33919 | D52: Law & Order | E52: 3 | F52: 7 | G52: 03.07 | H52: Self-Defense | J52: 7 | K52: 1990–2001 | L52: 1990-2001 (w epi names) | M52: #b91c1c
A53: 52 | B53: Not Started | C53: 33926 | D53: Law & Order | E53: 3 | F53: 8 | G53: 03.08 | H53: Prince of Darkness | J53: 8 | K53: 1990–2001 | L53: 1990-2001 (w epi names) | M53: #b91c1c
A54: 53 | B54: Not Started | C54: 33933 | D54: Law & Order | E54: 3 | F54: 9 | G54: 03.09 | H54: Point of View | J54: 9 | K54: 1990–2001 | L54: 1990-2001 (w epi names) | M54: #b91c1c
A55: 54 | B55: Not Started | C55: 33947 | D55: Law & Order | E55: 3 | F55: 10 | G55: 03.10 | H55: Consultation | J55: 10 | K55: 1990–2001 | L55: 1990-2001 (w epi names) | M55: #b91c1c
A56: 55 | B56: Not Started | C56: 33975 | D56: Law & Order | E56: 3 | F56: 11 | G56: 03.11 | H56: Extended Family | J56: 11 | K56: 1990–2001 | L56: 1990-2001 (w epi names) | M56: #b91c1c
A57: 56 | B57: Not Started | C57: 33982 | D57: Law & Order | E57: 3 | F57: 12 | G57: 03.12 | H57: Right to Counsel | J57: 12 | K57: 1990–2001 | L57: 1990-2001 (w epi names) | M57: #b91c1c
A58: 57 | B58: Not Started | C58: 34000 | D58: Homicide: Life on the Street | E58: 1 | F58: 1 | G58: 01.01 | H58: Gone for Goode | J58: 13 | K58: 1990–2001 | L58: 1990-2001 (w epi names) | M58: #d97706
A59: 58 | B59: Not Started | C59: 34003 | D59: Homicide: Life on the Street | E59: 1 | F59: 2 | G59: 01.02 | H59: Ghost of a Chance | J59: 15 | K59: 1990–2001 | L59: 1990-2001 (w epi names) | M59: #d97706
A60: 59 | B60: Not Started | C60: 34003 | D60: Law & Order | E60: 3 | F60: 13 | G60: 03.13 | H60: Night and Fog | J60: 14 | K60: 1990–2001 | L60: 1990-2001 (w epi names) | M60: #b91c1c
A61: 60 | B61: Not Started | C61: 34010 | D61: Homicide: Life on the Street | E61: 1 | F61: 3 | G61: 01.03 | H61: Night of the Dead Living | J61: 17 | K61: 1990–2001 | L61: 1990-2001 (w epi names) | M61: #d97706
A62: 61 | B62: Not Started | C62: 34010 | D62: Law & Order | E62: 3 | F62: 14 | G62: 03.14 | H62: Promises to Keep | J62: 16 | K62: 1990–2001 | L62: 1990-2001 (w epi names) | M62: #b91c1c
... A101: 100 | B101: Not Started | C101: 34479 | D101: Law & Order | E101: 4 | F101: 22 | G101: 04.22 | H101: Old Friends | J101: 57 | K101: 1990–2001 | L101: 1990-2001 (w epi names) | M101: #b91c1c
A102: 101 | B102: Not Started | C102: 34585 | D102: NY Undercover | E102: 1 | F102: 1 | G102: 01.01 | J102: 58 | K102: 1990–2001 | L102: 1990-2001 (w epi names) | M102: #64748b
A103: 102 | B103: Not Started | C103: 34592 | D103: NY Undercover | E103: 1 | F103: 2 | G103: 01.02 | J103: 59 | K103: 1990–2001 | L103: 1990-2001 (w epi names) | M103: #64748b
A104: 103 | B104: Not Started | C104: 34598 | D104: Law & Order | E104: 5 | F104: 1 | G104: 05.01 | H104: Second Opinion | J104: 60 | K104: 1990–2001 | L104: 1990-2001 (w epi names) | M104: #b91c1c
A105: 104 | B105: Not Started | C105: 34599 | D105: NY Undercover | E105: 1 | F105: 3 | G105: 01.03 | J105: 61 | K105: 1990–2001 | L105: 1990-2001 (w epi names) | M105: #64748b
A106: 105 | B106: Not Started | C106: 34605 | D106: Law & Order | E106: 5 | F106: 2 | G106: 05.02 | H106: Coma | J106: 62 | K106: 1990–2001 | L106: 1990-2001 (w epi names) | M106: #b91c1c
A107: 106 | B107: Not Started | C107: 34606 | D107: NY Undercover | E107: 1 | F107: 4 | G107: 01.04 | J107: 63 | K107: 1990–2001 | L107: 1990-2001 (w epi names) | M107: #64748b
A108: 107 | B108: Not Started | C108: 34612 | D108: Law & Order | E108: 5 | F108: 3 | G108: 05.03 | H108: Blue Bamboo | J108: 64 | K108: 1990–2001 | L108: 1990-2001 (w epi names) | M108: #b91c1c
A109: 108 | B109: Not Started | C109: 34613 | D109: NY Undercover | E109: 1 | F109: 5 | G109: 01.05 | J109: 65 | K109: 1990–2001 | L109: 1990-2001 (w epi names) | M109: #64748b
...

Sheet Crossovers
A1: Air Date | B1: Show | C1: Episode / Event | D1: Type / Note | E1: Extra Source Note | F1: Source Row
A2: 34754 | B2: Homicide | C2: Law & Disorder (Homicide S03E16) | D2: Cameo | F2: 3
A3: 35102 | B3: Law & Order | C3: Charm City (Law & Order S06E13) | D3: Two-part crossover | F3: 5
A4: 35104 | B4: Homicide | C4: For God and Country (Homicide S04E11) | D4: Two-part crossover | F4: 6
A5: 35376 | B5: NY Undercover | C5: Smack Is Back (New York Undercover S03E07) | D5: Guest | F5: 8
A6: 35746 | B6: Law & Order | C6: Baby, It's You (Law & Order S08E06) | D6: Two-part crossover | F6: 10
A7: 35748 | B7: Homicide | C7: Baby, It's You (Homicide S06E05) | D7: Two-part crossover | F7: 11
A8: 36208 | B8: Law & Order | C8: Sideshow (Law & Order S09E14) | D8: Two-part crossover | F8: 13
A9: 36210 | B9: Homicide | C9: Sideshow (Homicide S07E15) | D9: Two-part crossover | F9: 14
A10: 36437 | B10: SVU | C10: ...Or Just Look Like One (SVU S01E03) | D10: Guest | F10: 16
A11: 36574 | B11: SVU | C11: Entitled (SVU S01E15) | D11: Two-part crossover | F11: 18
A12: 36574 | B12: Law & Order | C12: Entitled (Law & Order S10E14) | D12: Two-part crossover | F12: 19
A13: 36579 | B13: Law & Order | C13: Fools for Love (Law & Order S10E15) | D13: Guest | F13: 21
... A67: 44658 | B67: OC | C67: Can't Knock the Hustle (Organized Crime S02E17) | D67: Cameo | F67: 120
A68: 44686 | B68: SVU | C68: Did You Believe in Miracles? (SVU S23E20) | D68: Cameo/ "Crossover" | E68: SVU scene cut from streaming | F68: 122
A69: 44686 | B69: OC | C69: Lost One (Organized Crime S02E20) | D69: Guest/ "Crossover" | F69: 123
A70: 44700 | B70: Law & Order | C70: Black and Blue (Law & Order S21E10) | D70: Guest | F70: 125
A71: 44700 | B71: OC | C71: Friend or Foe (Organized Crime S02E22) | D71: Cameo | F71: 127
A72: 44826 | B72: OC | C72: Gimme Shelter-- Part 1 (Organized Crime S3E01) | D72: Three-part crossover | F72: 129
A73: 44826 | B73: SVU | C73: Gimme Shelter-- Part 2 (SVU S24E01) | D73: Three-part crossover | F73: 130
A74: 44826 | B74: Law & Order | C74: Gimme Shelter-- Part 3 (Law & Order S22E01) | D74: Three-part crossover | F74: 131
A75: 44861 | B75: OC | C75: Behind Blue Eyes (Organized Crime S03E05) | D75: Guest | F75: 133
A76: 44931 | B76: SVU | C76: Jumped In (SVU S24E10) | D76: Guest | F76: 135
A77: 44952 | B77: SVU | C77: Blood Out (SVU S24E12) | D77: Cameo | F77: 137
A78: 45057 | B78: SVU | C78: Bad Things (SVU S24E21) | D78: Four-part crossover | F78: 139
A79: 45057 | B79: OC | C79: Shadowërk (Organized Crime S3E21) | D79: Four-part crossover | F79: 140
A80: 45064 | B80: SVU | C80: All Pain Is One Malady (SVU S24E22) | D80: Four-part crossover | F80: 141
... A88: 46030 | B88: SVU | C88: Purity (SVU S27E09) | D88: Two-part crossover | F88: 154

Sheet Methodology
A1: What this file is | B1: A single master viewing guide for the Law & Order universe entries present in your uploaded workbook.
A2: How to use it | B2: Go to Chronological Guide and watch from #1 downward. Mark the Status column as you go.
A3: Sort method | B3: Primary order is chronological air date. Same-day entries are ordered by show, season, and episode; crossover notes are shown in the notes column and in the Crossovers tab.
A4: Source tabs used | B4: 1990-2001 (w epi names), 2001-2011, 2011-2021, 2021-Present, Crossovers.
A5: Episode titles | B5: Titles are included where the uploaded workbook contained them. The later era tabs mostly contained episode numbers and dates only, so title cells may be blank there.
A6: Source Watch # | B6: Preserves the workbook manual watch-order index where available.
A7: Unresolved manual watch-order rows | B7: 25
A8: Parsed airing entries before de-duplication | B8: 1796
A9: Guide entries after de-duplication | B9: 1796
A11: Trakt Sync | B11: A Trakt Sync sheet and external Python sync package were added. The script updates Chronological Guide!B:B from your Trakt watched history after you authorize it with your own Trakt API app.
A12: Privacy | B12: No Trakt credentials or tokens are stored in this workbook. The script stores them locally in trakt_token.json on your computer.
A13: Matching | B13: Matching is by workbook show name → Trakt slug → season/episode.

Sheet Trakt Sync
A1: Trakt Sync Setup
A2: What this adds | B2: Automatic syncing is possible, but Excel cannot safely connect to Trakt by itself without your Trakt OAuth/API credentials. This workbook is now prepared for syncing through the included Python script.
A3: How it works | B3: The script reads your Trakt watched history, matches entries by show + season + episode, then updates the Status column in the Chronological Guide sheet to Watched / Not Started.
A4: Files included | B4: Law_Order_Complete_Chronological_Viewing_Guide_Trakt_Ready.xlsx, trakt_sync_law_order.py, trakt_config.example.json, README_Trakt_Sync.txt
A5: Step 1 | B5: Create a Trakt API app at your Trakt account's API settings and copy the Client ID and Client Secret.
A6: Step 2 | B6: Rename trakt_config.example.json to trakt_config.json and paste your Client ID and Client Secret.
A7: Step 3 | B7: Install Python packages: pip install requests openpyxl
A8: Step 4 | B8: Run: python trakt_sync_law_order.py
A9: Step 5 | B9: On first run, the script shows a Trakt device-code login. Open the displayed verification URL, enter the code, then rerun or let it continue.
A10: Important | B10: I could not connect to your Trakt account from here because that requires your private OAuth credentials and a one-time authorization code.
A12: Show mapping used by the sync script
A13: Workbook Show | B13: Trakt Slug | C13: Status | D13: Notes
A14: Law & Order | B14: law-and-order | C14: Ready
A15: Homicide: Life on the Street | B15: homicide-life-on-the-street | C15: Ready
A16: Law & Order: Special Victims Unit | B16: law-and-order-special-victims-unit | C16: Ready
A17: Law & Order: Criminal Intent | B17: law-and-order-criminal-intent | C17: Ready
A18: Law & Order: Trial by Jury | B18: law-and-order-trial-by-jury | C18: Ready
A19: Conviction | B19: conviction | C19: Ready
A20: Law & Order: UK | B20: law-and-order-uk | C20: Ready
A21: Law & Order: LA | B21: law-and-order-la | C21: Ready
A22: Law & Order True Crime | B22: law-and-order-true-crime | C22: Ready
A23: Law & Order: Organized Crime | B23: law-and-order-organized-crime | C23: Ready
A24: Criminal Intent: Toronto | B24: criminal-intent-toronto | C24: Ready
A25: Deadline | B25: deadline | C25: Ready
A26: New York Undercover | B26: new-york-undercover | C26: Ready
A28: Generated | B28: 2026-07-03 14:39

Sheet Tracker Control
A1: LAW & ORDER MASTER TRACKER
A3: Viewing mode | B3: Only Unwatched | D3: How to use
A4: Next episode formula | B4: Uses the Chronological Guide status column | D4: 1 | E4: Sync from Trakt or update statuses manually in Chronological Guide.
A5: Best mobile view | B5: Open the Mobile View sheet or use the included web app | D5: 2 | E5: Choose Viewing mode above; Mobile View updates automatically in Excel 365/mobile.
A6: Bulk season marking | B6: Use the included web app, or fill Season Manager > Action and run apply_bulk_actions_to_excel.py | D6: 3 | E6: For phone use, open law_order_tracker_app/index.html and use Hide Watched + season buttons.
A7: Trakt sync | B7: Run sync_trakt_and_excel.py from the package | D7: 4 | E7: Export status JSON from the app and keep it as your backup/watch-state file.
A8: Status values | B8: Not Started / Watching / Watched / Skipped | D8: 5 | E8: Run apply_bulk_actions_to_excel.py when you use Season Manager bulk actions inside Excel.
A9: Last package update | B9: 2026-07-03 15:34 | D9: Compatibility | E9: No VBA/macros. Works better on Excel 365, Excel mobile, and browser.
A10: Workbook source | B10: Law_Order_Complete_Chronological_Viewing_Guide_Trakt_Ready.xlsx | D10: Tip | E10: Keep the Chronological Guide as the source of truth for Excel status.

Sheet Mobile View
A1: # | B1: Status | C1: Air Date | D1: Show | E1: Season | F1: Episode | G1: Code | H1: Title | I1: Crossover / Viewing Notes | J1: Source Watch # | K1: Era | L1: Source Tab | N1: Mobile-friendly Controls
A2: {=_xlfn._xlws.FILTER('Chronological Guide'!A2:L1797,SWITCH('Tracker Control'!$B$3,"Only Unwatched",'Chronological Guide'!B2:B1797<>"Watched","Only Watched",'Chronological Guide'!B2:B1797="Watched",'Chronological Guide'!A2:A1797>0),"No matching episodes")} | B2: Not Started | C2: 33129 | D2: Law & Order | E2: 1 | F2: 1 | G2: 1.01 | H2: Prescription for Death | I2: 0 | J2: 0 | K2: 1990–2001 | L2: 1990-2001 (w epi names) | N2: Mode | O2: Change this in Tracker Control!B3
A3: 2 | B3: Not Started | C3: 33136 | D3: Law & Order | E3: 1 | F3: 2 | G3: 1.02 | H3: Subterranean Homeboy Blues | I3: 0 | J3: 0 | K3: 1990–2001 | L3: 1990-2001 (w epi names) | N3: Hide watched | O3: Set mode to Only Unwatched
A4: 3 | B4: Not Started | C4: 33150 | D4: Law & Order | E4: 1 | F4: 9 | G4: 1.09 | H4: Indifference | I4: 0 | J4: 0 | K4: 1990–2001 | L4: 1990-2001 (w epi names) | N4: Mark watched | O4: Use Status in Chronological Guide, or the web app for one-tap actions
A5: 4 | B5: Not Started | C5: 33157 | D5: Law & Order | E5: 1 | F5: 3 | G5: 1.03 | H5: The Reaper's Helper | I5: 0 | J5: 0 | K5: 1990–2001 | L5: 1990-2001 (w epi names) | N5: Next episode | O5: First visible row when mode is Only Unwatched
A6: 5 | B6: Not Started | C6: 33169 | D6: Law & Order | E6: 1 | F6: 4 | G6: 1.04 | H6: Kiss the Girls and Make Them Die | I6: 0 | J6: 0 | K6: 1990–2001 | L6: 1990-2001 (w epi names) | N6: Phone tip | O6: Freeze row 1 and use search/filter inside Excel mobile
A7: 6 | B7: Not Started | C7: 33176 | D7: Law & Order | E7: 1 | F7: 5 | G7: 1.05 | H7: Happily Ever After | I7: 0 | J7: 0 | K7: 1990–2001 | L7: 1990-2001 (w epi names) | N7: Crossover tip | O7: Do not skip rows with viewing notes
A8: 7 | B8: Not Started | C8: 33190 | D8: Law & Order | E8: 1 | F8: 6 | G8: 1.06 | H8: Everybody's Favorite Bagman | I8: 0 | J8: 0 | K8: 1990–2001 | L8: 1990-2001 (w epi names) | N8: No macros | O8: Designed for mobile compatibility
A9: 8 | B9: Not Started | C9: 33197 | D9: Law & Order | E9: 1 | F9: 7 | G9: 1.07 | H9: By Hooker, By Crook | I9: 0 | J9: 0 | K9: 1990–2001 | L9: 1990-2001 (w epi names)
A10: 9 | B10: Not Started | C10: 33204 | D10: Law & Order | E10: 1 | F10: 8 | G10: 1.08 | H10: Poison Ivy | I10: 0 | J10: 0 | K10: 1990–2001 | L10: 1990-2001 (w epi names)
A11: 10 | B11: Not Started | C11: 33211 | D11: Law & Order | E11: 1 | F11: 10 | G11: 1.1 | H11: Prisoner of Love | I11: 0 | J11: 0 | K11: 1990–2001 | L11: 1990-2001 (w epi names)
A12: 11 | B12: Not Started | C12: 33218 | D12: Law & Order | E12: 1 | F12: 11 | G12: 1.11 | H12: Out of the Half-Light | I12: 0 | J12: 0 | K12: 1990–2001 | L12: 1990-2001 (w epi names)
A13: 12 | B13: Not Started | C13: 33246 | D13: Law & Order | E13: 1 | F13: 12 | G13: 1.12 | H13: Life Choice | I13: 0 | J13: 0 | K13: 1990–2001 | L13: 1990-2001 (w epi names)
A14: 13 | B14: Not Started | C14: 33253 | D14: Law & Order | E14: 1 | F14: 13 | G14: 1.13 | H14: A Death in the Family | I14: 0 | J14: 0 | K14: 1990–2001 | L14: 1990-2001 (w epi names)
A15: 14 | B15: Not Started | C15: 33274 | D15: Law & Order | E15: 1 | F15: 14 | G15: 1.14 | H15: The Violence of Summer | I15: 0 | J15: 0 | K15: 1990–2001 | L15: 1990-2001 (w epi names)
A16: 15 | B16: Not Started | C16: 33281 | D16: Law & Order | E16: 1 | F16: 15 | G16: 1.15 | H16: The Torrents of Greed | I16: 0 | J16: 0 | K16: 1990–2001 | L16: 1990-2001 (w epi names)
A17: 16 | B17: Not Started | C17: 33288 | D17: Law & Order | E17: 1 | F17: 16 | G17: 1.16 | H17: The Torrents of Greed (Part II) | I17: 0 | J17: 0 | K17: 1990–2001 | L17: 1990-2001 (w epi names)
A18: 17 | B18: Not Started | C18: 33295 | D18: Law & Order | E18: 1 | F18: 17 | G18: 1.17 | H18: Mushrooms | I18: 0 | J18: 0 | K18: 1990–2001 | L18: 1990-2001 (w epi names)
A19: 18 | B19: Not Started | C19: 33309 | D19: Law & Order | E19: 1 | F19: 18 | G19: 1.18 | H19: The Secret Sharers | I19: 0 | J19: 0 | K19: 1990–2001 | L19: 1990-2001 (w epi names)
A20: 19 | B20: Not Started | C20: 33316 | D20: Law & Order | E20: 1 | F20: 19 | G20: 1.19 | H20: The Serpent's Tooth | I20: 0 | J20: 0 | K20: 1990–2001 | L20: 1990-2001 (w epi names)
... A45: 44 | B45: Not Started | C45: 33736 | D45: Law & Order | E45: 2 | F45: 22 | G45: 2.22 | H45: The Working Stiff | I45: 0 | J45: 0 | K45: 1990–2001 | L45: 1990-2001 (w epi names)
A46: 45 | B46: Not Started | C46: 33870 | D46: Law & Order | E46: 3 | F46: 1 | G46: 3.01 | H46: Skin Deep | I46: Homicide Season 1-7 & movie | J46: 1 | K46: 1990–2001 | L46: 1990-2001 (w epi names)
A47: 46 | B47: Not Started | C47: 33877 | D47: Law & Order | E47: 3 | F47: 2 | G47: 3.02 | H47: Conspiracy | I47: NY Undercover Season 1-4 | J47: 2 | K47: 1990–2001 | L47: 1990-2001 (w epi names)
A48: 47 | B48: Not Started | C48: 33884 | D48: Law & Order | E48: 3 | F48: 3 | G48: 3.03 | H48: Forgiveness | I48: SVU Season 1-2 | J48: 3 | K48: 1990–2001 | L48: 1990-2001 (w epi names)
A49: 48 | B49: Not Started | C49: 33891 | D49: Law & Order | E49: 3 | F49: 4 | G49: 3.04 | H49: The Corporate Veil | I49: Deadline Season 1 | J49: 4 | K49: 1990–2001 | L49: 1990-2001 (w epi names)
A50: 49 | B50: Not Started | C50: 33898 | D50: Law & Order | E50: 3 | F50: 5 | G50: 3.05 | H50: Wedded Bliss | I50: *= aired out of order | J50: 5 | K50: 1990–2001 | L50: 1990-2001 (w epi names)
A51: 50 | B51: Not Started | C51: 33912 | D51: Law & Order | E51: 3 | F51: 6 | G51: 3.06 | H51: Helpless | I51: 0 | J51: 6 | K51: 1990–2001 | L51: 1990-2001 (w epi names)
A52: 51 | B52: Not Started | C52: 33919 | D52: Law & Order | E52: 3 | F52: 7 | G52: 3.07 | H52: Self-Defense | I52: 0 | J52: 7 | K52: 1990–2001 | L52: 1990-2001 (w epi names)
A53: 52 | B53: Not Started | C53: 33926 | D53: Law & Order | E53: 3 | F53: 8 | G53: 3.08 | H53: Prince of Darkness | I53: 0 | J53: 8 | K53: 1990–2001 | L53: 1990-2001 (w epi names)
A54: 53 | B54: Not Started | C54: 33933 | D54: Law & Order | E54: 3 | F54: 9 | G54: 3.09 | H54: Point of View | I54: 0 | J54: 9 | K54: 1990–2001 | L54: 1990-2001 (w epi names)
A55: 54 | B55: Not Started | C55: 33947 | D55: Law & Order | E55: 3 | F55: 10 | G55: 3.1 | H55: Consultation | I55: 0 | J55: 10 | K55: 1990–2001 | L55: 1990-2001 (w epi names)
A56: 55 | B56: Not Started | C56: 33975 | D56: Law & Order | E56: 3 | F56: 11 | G56: 3.11 | H56: Extended Family | I56: 0 | J56: 11 | K56: 1990–2001 | L56: 1990-2001 (w epi names)
A57: 56 | B57: Not Started | C57: 33982 | D57: Law & Order | E57: 3 | F57: 12 | G57: 3.12 | H57: Right to Counsel | I57: 0 | J57: 12 | K57: 1990–2001 | L57: 1990-2001 (w epi names)
A58: 57 | B58: Not Started | C58: 34000 | D58: Homicide: Life on the Street | E58: 1 | F58: 1 | G58: 1.01 | H58: Gone for Goode | I58: 0 | J58: 13 | K58: 1990–2001 | L58: 1990-2001 (w epi names)
A59: 58 | B59: Not Started | C59: 34003 | D59: Homicide: Life on the Street | E59: 1 | F59: 2 | G59: 1.02 | H59: Ghost of a Chance | I59: 0 | J59: 15 | K59: 1990–2001 | L59: 1990-2001 (w epi names)
A60: 59 | B60: Not Started | C60: 34003 | D60: Law & Order | E60: 3 | F60: 13 | G60: 3.13 | H60: Night and Fog | I60: 0 | J60: 14 | K60: 1990–2001 | L60: 1990-2001 (w epi names)
A61: 60 | B61: Not Started | C61: 34010 | D61: Homicide: Life on the Street | E61: 1 | F61: 3 | G61: 1.03 | H61: Night of the Dead Living | I61: 0 | J61: 17 | K61: 1990–2001 | L61: 1990-2001 (w epi names)
A62: 61 | B62: Not Started | C62: 34010 | D62: Law & Order | E62: 3 | F62: 14 | G62: 3.14 | H62: Promises to Keep | I62: 0 | J62: 16 | K62: 1990–2001 | L62: 1990-2001 (w epi names)
... A101: 100 | B101: Not Started | C101: 34479 | D101: Law & Order | E101: 4 | F101: 22 | G101: 4.22 | H101: Old Friends | I101: 0 | J101: 57 | K101: 1990–2001 | L101: 1990-2001 (w epi names)
A102: 101 | B102: Not Started | C102: 34585 | D102: NY Undercover | E102: 1 | F102: 1 | G102: 1.01 | H102: 0 | I102: 0 | J102: 58 | K102: 1990–2001 | L102: 1990-2001 (w epi names)
...

Sheet Season Manager
A1: Show | B1: Season | C1: Episodes | D1: Watched | E1: Remaining | F1: Completion % | G1: Bulk Action | H1: Notes
A2: Law & Order | B2: 1 | C2: =COUNTIFS('Chronological Guide'!$D:$D,A2,'Chronological Guide'!$E:$E,B2) | D2: =COUNTIFS('Chronological Guide'!$D:$D,A2,'Chronological Guide'!$E:$E,B2,'Chronological Guide'!$B:$B,"Watched") | E2: =C2-D2 | F2: =IF(C2=0,0,D2/C2) | G2: No Action | H2: Set action, then run apply_bulk_actions_to_excel.py or use the web app.
A3: Law & Order | B3: 2 | C3: =COUNTIFS('Chronological Guide'!$D:$D,A3,'Chronological Guide'!$E:$E,B3) | D3: =COUNTIFS('Chronological Guide'!$D:$D,A3,'Chronological Guide'!$E:$E,B3,'Chronological Guide'!$B:$B,"Watched") | E3: =C3-D3 | F3: =IF(C3=0,0,D3/C3) | G3: No Action | H3: Set action, then run apply_bulk_actions_to_excel.py or use the web app.
A4: Law & Order | B4: 3 | C4: =COUNTIFS('Chronological Guide'!$D:$D,A4,'Chronological Guide'!$E:$E,B4) | D4: =COUNTIFS('Chronological Guide'!$D:$D,A4,'Chronological Guide'!$E:$E,B4,'Chronological Guide'!$B:$B,"Watched") | E4: =C4-D4 | F4: =IF(C4=0,0,D4/C4) | G4: No Action | H4: Set action, then run apply_bulk_actions_to_excel.py or use the web app.
A5: Homicide: Life on the Street | B5: 1 | C5: =COUNTIFS('Chronological Guide'!$D:$D,A5,'Chronological Guide'!$E:$E,B5) | D5: =COUNTIFS('Chronological Guide'!$D:$D,A5,'Chronological Guide'!$E:$E,B5,'Chronological Guide'!$B:$B,"Watched") | E5: =C5-D5 | F5: =IF(C5=0,0,D5/C5) | G5: No Action | H5: Set action, then run apply_bulk_actions_to_excel.py or use the web app.
A6: Law & Order | B6: 4 | C6: =COUNTIFS('Chronological Guide'!$D:$D,A6,'Chronological Guide'!$E:$E,B6) | D6: =COUNTIFS('Chronological Guide'!$D:$D,A6,'Chronological Guide'!$E:$E,B6,'Chronological Guide'!$B:$B,"Watched") | E6: =C6-D6 | F6: =IF(C6=0,0,D6/C6) | G6: No Action | H6: Set action, then run apply_bulk_actions_to_excel.py or use the web app.
A7: Homicide: Life on the Street | B7: 2 | C7: =COUNTIFS('Chronological Guide'!$D:$D,A7,'Chronological Guide'!$E:$E,B7) | D7: =COUNTIFS('Chronological Guide'!$D:$D,A7,'Chronological Guide'!$E:$E,B7,'Chronological Guide'!$B:$B,"Watched") | E7: =C7-D7 | F7: =IF(C7=0,0,D7/C7) | G7: No Action | H7: Set action, then run apply_bulk_actions_to_excel.py or use the web app.
A8: NY Undercover | B8: 1 | C8: =COUNTIFS('Chronological Guide'!$D:$D,A8,'Chronological Guide'!$E:$E,B8) | D8: =COUNTIFS('Chronological Guide'!$D:$D,A8,'Chronological Guide'!$E:$E,B8,'Chronological Guide'!$B:$B,"Watched") | E8: =C8-D8 | F8: =IF(C8=0,0,D8/C8) | G8: No Action | H8: Set action, then run apply_bulk_actions_to_excel.py or use the web app.
A9: Law & Order | B9: 5 | C9: =COUNTIFS('Chronological Guide'!$D:$D,A9,'Chronological Guide'!$E:$E,B9) | D9: =COUNTIFS('Chronological Guide'!$D:$D,A9,'Chronological Guide'!$E:$E,B9,'Chronological Guide'!$B:$B,"Watched") | E9: =C9-D9 | F9: =IF(C9=0,0,D9/C9) | G9: No Action | H9: Set action, then run apply_bulk_actions_to_excel.py or use the web app.
A10: Homicide: Life on the Street | B10: 3 | C10: =COUNTIFS('Chronological Guide'!$D:$D,A10,'Chronological Guide'!$E:$E,B10) | D10: =COUNTIFS('Chronological Guide'!$D:$D,A10,'Chronological Guide'!$E:$E,B10,'Chronological Guide'!$B:$B,"Watched") | E10: =C10-D10 | F10: =IF(C10=0,0,D10/C10) | G10: No Action | H10: Set action, then run apply_bulk_actions_to_excel.py or use the web app.
A11: NY Undercover | B11: 2 | C11: =COUNTIFS('Chronological Guide'!$D:$D,A11,'Chronological Guide'!$E:$E,B11) | D11: =COUNTIFS('Chronological Guide'!$D:$D,A11,'Chronological Guide'!$E:$E,B11,'Chronological Guide'!$B:$B,"Watched") | E11: =C11-D11 | F11: =IF(C11=0,0,D11/C11) | G11: No Action | H11: Set action, then run apply_bulk_actions_to_excel.py or use the web app.
A12: Law & Order | B12: 6 | C12: =COUNTIFS('Chronological Guide'!$D:$D,A12,'Chronological Guide'!$E:$E,B12) | D12: =COUNTIFS('Chronological Guide'!$D:$D,A12,'Chronological Guide'!$E:$E,B12,'Chronological Guide'!$B:$B,"Watched") | E12: =C12-D12 | F12: =IF(C12=0,0,D12/C12) | G12: No Action | H12: Set action, then run apply_bulk_actions_to_excel.py or use the web app.
A13: Homicide: Life on the Street | B13: 4 | C13: =COUNTIFS('Chronological Guide'!$D:$D,A13,'Chronological Guide'!$E:$E,B13) | D13: =COUNTIFS('Chronological Guide'!$D:$D,A13,'Chronological Guide'!$E:$E,B13,'Chronological Guide'!$B:$B,"Watched") | E13: =C13-D13 | F13: =IF(C13=0,0,D13/C13) | G13: No Action | H13: Set action, then run apply_bulk_actions_to_excel.py or use the web app.
... A99: Law & Order: SVU | B99: 27 | C99: =COUNTIFS('Chronological Guide'!$D:$D,A99,'Chronological Guide'!$E:$E,B99) | D99: =COUNTIFS('Chronological Guide'!$D:$D,A99,'Chronological Guide'!$E:$E,B99,'Chronological Guide'!$B:$B,"Watched") | E99: =C99-D99 | F99: =IF(C99=0,0,D99/C99) | G99: No Action | H99: Set action, then run apply_bulk_actions_to_excel.py or use the web app.

Sheet Tracker Dashboard
A1: LAW & ORDER WATCH TRACKER DASHBOARD
A3: Total Episodes | B3: =COUNTA('Chronological Guide'!A2:A1797) | D3: Workflow
A4: Watched | B4: =COUNTIF('Chronological Guide'!B2:B1797,"Watched") | D4: 1. Use Trakt sync to import watched history.
A5: Remaining | B5: =B3-B4 | D5: 2. Use Tracker Control to switch between all/unwatched/watched.
A6: Completion | B6: =IF(B3=0,0,B4/B3) | D6: 3. Use Mobile View for a clean list on phone.
A7: Next Episode # | B7: =IFERROR(INDEX(FILTER('Chronological Guide'!A2:A1797,'Chronological Guide'!B2:B1797<>"Watched"),1),"Complete") | D7: 4. Use the web app for fast one-tap marking and season bulk actions.
A8: Next Show | B8: =IFERROR(INDEX(FILTER('Chronological Guide'!D2:D1797,'Chronological Guide'!B2:B1797<>"Watched"),1),"Complete") | D8: 5. Export JSON from the app as backup.
A9: Next Code | B9: =IFERROR(INDEX(FILTER('Chronological Guide'!G2:G1797,'Chronological Guide'!B2:B1797<>"Watched"),1),"") | D9: 6. Run apply_bulk_actions_to_excel.py for Season Manager actions.
A10: Next Title | B10: =IFERROR(INDEX(FILTER('Chronological Guide'!H2:H1797,'Chronological Guide'!B2:B1797<>"Watched"),1),"") | D10: 7. Keep this workbook and status JSON together.

Sheet Web App Guide
A1: MOBILE WEB APP GUIDE
A3: What it does | B3: Mobile-first tracker with Hide Watched, Next Episode, search, filters, and one-tap season/show marking.
A4: How to open | B4: Unzip the package, open law_order_tracker_app/index.html in Chrome/Edge/Safari.
A5: Works offline | B5: Yes. The episode database is included in the app. Watch status is saved in your browser localStorage.
A6: Backup | B6: Use Export Status JSON inside the app.
A7: Restore | B7: Use Import Status JSON inside the app.
A8: Trakt | B8: Run sync_trakt_and_excel.py to pull watched status from Trakt into Excel; use exported JSON for the app.
A9: Excel mobile | B9: Use the Mobile View tab and Tracker Control!B3 dropdown.
A10: Bulk seasons | B10: Best on phone/web app: open Season Manager in the app and tap Mark Watched.
A11: No VBA | B11: Designed to work on mobile; Excel macros are intentionally avoided.

Sheet Mobile App Setup
A1: Law & Order Tracker — Mobile App / Vercel Setup
A2: Use the included law_order_tracker_app folder as a phone-friendly app.
A3: Local automatic sync | B3: python sync_trakt_and_excel.py --loop --minutes 15
A4: Update missing episodes from Trakt | B4: python update_episode_catalog_from_trakt.py
A5: Deploy to phone | B5: Upload package folder to GitHub, import repo in Vercel, open Vercel URL on phone, Add to Home Screen
A6: Cloud auto-sync | B6: Set GitHub Secrets TRAKT_CLIENT_ID, TRAKT_CLIENT_SECRET, TRAKT_TOKEN_JSON and enable the included GitHub Action.
